<?xml version='1.0'?>

<robot name="my_robot" xmlns:xacro="http://www.ros.org/wiki/xacro">
  <!-- color references: however gazebo has trouble urdf to sdf
    and evidently rviz has trouble sdf to urdf -->
  <material name="blue">
    <color rgba="0 0 0.8 1"/>
  </material>
  <material name="black">
    <color rgba="0 0 0 1"/>
  </material>
  <material name="white">
    <color rgba="1 1 1 1"/>
  </material>
  <!-- so we do this... --> 
  <gazebo reference="left_wheel">
    <material>Gazebo/Green</material>
  </gazebo>
  <gazebo reference="right_wheel">
    <material>Gazebo/Green</material>
  </gazebo>
  <gazebo reference="chassis">
    <material>Gazebo/Blue</material>
  </gazebo>
  <gazebo reference="camera">
    <material>Gazebo/Red</material>
  </gazebo>

  <!-- gazebo plugins for the wheels, camera and hokuyo sensors-->
  <xacro:include filename="$(find my_robot)/urdf/my_robot.gazebo" />

  <link name="robot_footprint"></link>

  <joint name="robot_footprint_joint" type="fixed">
    <origin xyz="0 0 0" rpy="0 0 0" />
    <parent link="robot_footprint"/>
    <child link="chassis" />
  </joint>

  <link name='chassis'>
    <pose>0 0 0.1 0 0 0</pose>

    <inertial>
      <mass value="15.0"/>
      <origin xyz="0.0 0 0" rpy=" 0 0 0"/>
      <inertia
          ixx="0.1" ixy="0" ixz="0"
          iyy="0.1" iyz="0"
          izz="0.1"
      />
    </inertial>

    <collision name='collision'>
      <origin xyz="0 0 0" rpy=" 0 0 0"/> 
      <geometry>
        <box size=".4 .2 .1"/>
      </geometry>
    </collision>

    <visual name='chassis_visual'>
      <origin xyz="0 0 0" rpy=" 0 0 0"/>
      <geometry>
        <box size=".4 .2 .1"/>
      </geometry>
    </visual>


    <collision name='back_caster_collision'>
      <origin xyz="-0.15 0 -0.05" rpy=" 0 0 0"/>
      <geometry>
        <sphere radius="0.0499"/>
      </geometry>
    </collision>

    <visual name='back_caster_visual'>
      <origin xyz="-0.15 0 -0.05" rpy=" 0 0 0"/>
      <geometry>
        <sphere radius="0.05"/>
      </geometry>
    </visual>

    <collision name='front_caster_collision'>
      <origin xyz="0.15 0 -0.05" rpy="0 0 0"/>
      <geometry>
        <sphere radius="0.0499"/>
      </geometry>
    </collision>

    <visual name='front_caster_visual'>
      <origin xyz="0.15 0 -0.05" rpy="0 0 0"/>
      <geometry>
        <sphere radius="0.05"/>
      </geometry>
    </visual>
  </link>

  <!-- wheels -->
  <link name='left_wheel'>
    <inertial>
      <mass value="5.0"/>
      <origin xyz="0 0 0" rpy="0 1.5707 1.5707"/>
      <inertia
          ixx="0.1" ixy="0" ixz="0"
          iyy="0.1" iyz="0"
          izz="0.1"
      />
    </inertial>
    <collision name='left_wheel_collision'>
      <origin xyz="0 0 0" rpy="1.5707 0 0"/> 
      <geometry>
        <cylinder radius="0.1" length="0.05"/>
      </geometry>
    </collision>
    <visual name='left_wheel_visual'>
      <origin xyz="0 0 0" rpy="1.5707 0 0"/> 
      <geometry>
        <cylinder radius="0.1" length="0.05"/>
      </geometry>
      <material name="blue">
        <color rgba="0 0 0.8 1"/>
      </material>
    </visual>
  </link>
  
  <link name='right_wheel'>
    <inertial>
      <mass value="5.0"/>
      <origin xyz="0 0 0" rpy="0 1.5707 1.5707"/>
      <inertia
          ixx="0.1" ixy="0" ixz="0"
          iyy="0.1" iyz="0"
          izz="0.1"
      />
    </inertial>
    <collision name='right_wheel_collision'>
      <origin xyz="0 0 0" rpy="1.5707 0 0"/> 
      <geometry>
        <cylinder radius="0.1" length="0.05"/>
      </geometry>
    </collision>
    <visual name='right_wheel_visual'>
      <origin xyz="0 0 0" rpy="1.5707 0 0"/> 
      <geometry>
        <cylinder radius="0.1" length="0.05"/>
      </geometry>
    </visual>
  </link>

  <!-- wheel joints -->
  <joint type="continuous" name="left_wheel_hinge">
    <origin xyz="0 0.15 0" rpy="0 0 0"/>
    <child link="left_wheel"/>
    <parent link="chassis"/>
    <axis xyz="0 1 0" rpy="0 0 0"/>
    <limit effort="10000" velocity="1000"/>
    <dynamics damping="1.0" friction="1.0"/>
  </joint>
  <joint type="continuous" name="right_wheel_hinge">
    <origin xyz="0 -0.15 0" rpy="0 0 0"/>
    <child link="right_wheel"/>
    <parent link="chassis"/>
    <axis xyz="0 1 0" rpy="0 0 0"/>
    <limit effort="10000" velocity="1000"/>
    <dynamics damping="1.0" friction="1.0"/>
  </joint>

  <!-- Camera sensor -->
  <link name="camera">
  <box_inertia m="0.1" x="0.05" y="0.05" d="0.05"/>
    <inertial>
      <mass value="0.1"/>
      <origin xyz="0.0 0 0" rpy="0 0 0"/>
      <inertia
          ixx="0.000001" ixy="0" ixz="0"
          iyy="0.000001" iyz="0"
          izz="0.000001"
      />
    </inertial>
    <collision name="camera_collision">
      <origin xyz="0 0 0" rpy=" 0 0 0"/> 
      <geometry>
        <box size="0.05 0.05 0.05"/>
      </geometry>
    </collision>

    <visual name="camera_visual">
      <origin xyz="0 0 0" rpy=" 0 0 0"/> 
      <geometry>
        <box size="0.05 0.05 0.05"/>
      </geometry>
    </visual>
  </link>
  <joint type="fixed" name="camera_joint">
    <origin xyz="0.2 0 0" rpy="0 0 0"/>
    <child link="camera"/>
    <parent link="chassis"/>
    <axis xyz="0 1 0" rpy="0 0 0"/>
  </joint>

  <!-- Hokuyo lidar sensor -->
  <link name="hokuyo">
    <inertial>
      <mass value="0.00001"/>
      <origin xyz="0.0 0 0" rpy="0 0 0"/>
      <inertia
          ixx="0.000001" ixy="0" ixz="0"
          iyy="0.000001" iyz="0"
          izz="0.000001"
      />
    </inertial>
    <collision name="hokuyo_collision">
      <origin xyz="0 0 -0.015" rpy=" 0 0 0"/> 
      <geometry>
        <box size="0.1 0.1 0.1"/>
      </geometry>
    </collision>
    <visual name="hokuyo_visual">
      <origin xyz="0 0 0" rpy=" 0 0 0"/> 
      <geometry>
        <mesh filename="package://my_robot/meshes/hokuyo.dae"/>
      </geometry>
    </visual>
  </link>
  <joint type="fixed" name="hokuyo_joint">
    <origin xyz="0.15 0 0.1" rpy="0 0 0"/>
    <child link="hokuyo"/>
    <parent link="chassis"/>
    <axis xyz="0 1 0" rpy="0 0 0"/>
  </joint>
</robot>
